<mujoco model="a3">
    <!-- 定义使用弧度制 -->
    <compiler angle="radian"/>

    <option timestep="0.001" cone="pyramidal" jacobian="dense" solver="Newton" iterations="50" tolerance="1e-10"/>
    <size njmax="1200" nconmax="400"/>

    <!-- 定义了模型中使用的纹理、材料和其它资源 -->
    <!-- <texture> 定义了用于渲染的纹理，如天空盒、机器人身体的纹理等。 -->
    <!-- <material> 定义了材质，关联了纹理并设置了颜色等属性。 -->
    <asset>
        <texture type="skybox" builtin="gradient" rgb1=".3 .5 .7" rgb2="0 0 0" width="512"
            height="512" />
        <texture name="body" type="cube" builtin="flat" mark="cross" width="127" height="1278"
            rgb1="0.8 0.6 0.4" rgb2="0.8 0.6 0.4" markrgb="1 1 1" random="0.01" />
        <material name="body" texture="body" texuniform="true" rgba="0.8 0.6 .4 1" />
        <texture name="grid" type="2d" builtin="checker" width="512" height="512" rgb1=".1 .2 .3"
            rgb2=".2 .3 .4" />
        <material name="grid" texture="grid" texrepeat="1 1" texuniform="true" reflectance=".2" />
    </asset>

    <!-- 定义了默认的几何形状、关节和其他元素的属性。 -->
    <!-- <motor> 定义了默认的电机属性，如控制范围和控制是否受限。 -->
    <!-- <geom> 定义了默认的几何体属性，如形状、摩擦系数、材质等。 -->
    <!-- <joint> 定义了默认的关节属性，如阻尼、刚度、限位等。 -->
    <default>
        <motor ctrllimited="false" forcelimited="false"/>
        <default class="body">
            <geom type="capsule" condim="1" friction=".7" solimp=".9 .99 .003" solref=".015 1"
                material="body" />
            <joint damping="0.2" limited="true"/>
        </default>
    </default>

    <!-- 定义了视觉设置，如渲染质量、阴影大小、全局分辨率等。 -->
    <visual>
        <map force="0.1" zfar="30" />
        <rgba haze="0.15 0.25 0.35 1" />
        <quality shadowsize="4096" />
        <global offwidth="800" offheight="800" />
    </visual>

    <worldbody>
        <geom name="floor" size="0 0 .05" type="plane" material="grid" condim="3" />
        <light name="spotlight" mode="targetbodycom" target="torso"
            diffuse=".8 .8 .8" specular="0.3 0.3 0.3" pos="0 -20 4" cutoff="10" />
        <body name="torso" pos="0 0 1.5" childclass="body">
            <light name="top" pos="0 0 2" mode="trackcom" />
            <camera name="back" pos="-3 0 1" xyaxes="0 -1 0 1 0 2" mode="trackcom" />
            <camera name="side" pos="0 -3 1" xyaxes="1 0 0 0 1 2" mode="trackcom" />
            <freejoint name="root" />
            <geom name="torso" type="sphere" size="0.14" pos="0 0 -0.05" rgba="0.4 0.4 0.4 1" />
            <body name="head" pos="0 0 .19">
                <geom name="head" type="sphere" size="0.1" rgba="0 0.6 1 1" />
                <camera name="egocentric" pos=".09 0 0" xyaxes="0 -1 0 .1 0 1" fovy="80" />
            </body>
            <body name="lower_waist" pos="-.01 0 -.26">
                <geom name="lower_waist" fromto="0 -.06 0 0 .06 0" size=".06" rgba="1 0.6 0 1" />
                <body name="pelvis" pos="0 0 -.165">
                    <geom name="butt" type="sphere" size="0.08" rgba="1 0 0 0.8" />
                    <body name="right_thigh" pos="0 -.1 -.1">
                        <joint name="right_hip_y" axis="0 1 0" range="-2.0944 0.7854" armature="0.1925"/>
                        <joint name="right_hip_x" axis="1 0 0" range="-0.7854 0.34907" armature="0.1813"/>
                        <joint name="right_hip_z" axis="0 0 1" range="-0.5236 0.7854" armature="0.1237"/>
                        <geom name="right_thigh" fromto="0 -.03 0 0 -.03 -.3" size=".05" rgba="0 1 0 1" />
                        <body name="right_shin" pos="0 0 -.4">
                            <joint name="right_knee" pos="0 0 .02" axis="0 1 0" range="0 2.618" armature="0.1305"/>
                            <geom name="right_shin" fromto="0 -.03 -.03 0 -.03 -.3" size=".05"
                                rgba="1 1 0 1" />
                            <body name="right_foot" pos="0 0 -.4">
                                <joint name="right_ankle_x" pos="0 0 .04" axis="1 0 0" range="-0.61086 0.7854" armature="0.0653"/>
                                <joint name="right_ankle_y" pos="0 0 .08" axis="0 1 0" range="-1.4835 0.95993" armature="0.1337"/>
                                <geom name="right_foot" type="box" contype="0" conaffinity="0" size="0.1 0.05 0.03" pos=".02 -.03 0"/>
                                <site name="rf_force" size="0.01" pos="0.03 0 -.03"/>
                                <geom name="right_foot_sole" condim="3" group="0" type="box" size="0.1 0.05 0.01" pos="0.02 -.03 -.03" rgba="0 0 1 1"/>
                            </body>
                        </body>
                    </body>
                    <body name="left_thigh" pos="0 .1 -.1">
                        <joint name="left_hip_y" axis="0 1 0" range="-2.0944 0.7854" armature="0.1925"/>
                        <joint name="left_hip_x" axis="1 0 0" range="-0.34907 0.7854" armature="0.1813"/>
                        <joint name="left_hip_z" axis="0 0 1" range="-0.7854 0.5236" armature="0.1237"/>

                        <geom name="left_thigh" fromto="0 .03 0 0 .03 -.3" size=".05" rgba="0 1 0 1" />
                        <body name="left_shin" pos="0 0 -.4">
                            <joint name="left_knee" pos="0 0 .02" axis="0 1 0" range="0 2.618" armature="0.1305"/>
                            <geom name="left_shin" fromto="0 .03 -.03 0 .03 -.3" size=".05"
                                rgba="1 1 0 1" />
                            <body name="left_foot" pos="0 0 -.4">
                                <joint name="left_ankle_x" pos="0 0 .04" axis="1 0 0" range="-0.7854 0.61086" armature="0.0653"/>
                                <joint name="left_ankle_y" pos="0 0 .08" axis="0 1 0" range="-1.4835 0.95993" armature="0.1337"/>
                                <geom name="left_foot" type="box" contype="0" conaffinity="0" size="0.1 0.05 0.03" pos=".02 .03 0"/>
                                <site name="lf_force" size="0.01" pos="0.03 0 -.03"/>
                                <geom name="left_foot_sole" condim="3" group="0" type="box" size="0.1 0.05 0.01" pos="0.02 .03 -.03" rgba="1 0 0 1"/>
                            </body>
                        </body>
                    </body>
                </body>
            </body>
            <body name="right_upper_arm" pos="0 -.17 .06">
                <joint name="right_shoulder1" axis="0 1 0" range="-3.1416 1.0472" armature="0.121"/>
                <joint name="right_shoulder2" axis="1 0 0" range="-1.7453 0.17453" armature="0.121"/>
                <geom name="right_upper_arm" contype="0" conaffinity="0" fromto="0 0 0 .15 -.15 -.15" size=".04 .15"
                    rgba="0 0 1 1" />
                <body name="right_lower_arm" pos=".18 -.18 -.18">
                    <joint name="right_elbow" axis="0 1 0" range="-2.5307 0" armature="0.1054"/>
                    <geom name="right_lower_arm" contype="0" conaffinity="0" fromto=".01 .01 .01 .14 .14 .14" size=".04"
                        rgba="1 0 0.6 1" />
                    <body name="right_hand" pos=".18 .18 .18">
                        <geom name="right_hand" contype="0" conaffinity="0" type="sphere" size=".04" zaxis="1 1 1" />
                    </body>
                </body>
            </body>
            <body name="left_upper_arm" pos="0 .17 .06">
                <joint name="left_shoulder1" axis="0 1 0" range="-3.1416 1.0472" armature="0.121"/>
                <joint name="left_shoulder2" axis="1 0 0" range="-0.17453 1.7453" armature="0.121"/>
                <geom name="left_upper_arm" contype="0" conaffinity="0" fromto="0 0 0 .15 .15 -.15" size=".04 .15"
                    rgba="0 0 1 1" />
                <body name="left_lower_arm" pos=".18 .18 -.18">
                    <joint name="left_elbow" axis="0 1 0" range="-2.5307 0" armature="0.1054"/>
                    <geom name="left_lower_arm" contype="0" conaffinity="0" fromto=".01 -.01 .01 .14 -.14 .14" size=".04"
                        rgba="1 0 0.6 1" />
                    <body name="left_hand" pos=".18 -.18 .18">
                        <geom name="left_hand" contype="0" conaffinity="0" type="sphere" size=".04" zaxis="1 -1 1" />
                    </body>
                </body>
            </body>
        </body>
    </worldbody>

    <actuator>
        <motor name="right_hip_y_motor" joint="right_hip_y" />
        <motor name="right_hip_x_motor" joint="right_hip_x" />
        <motor name="right_hip_z_motor" joint="right_hip_z" />
        <motor name="right_knee_motor" joint="right_knee" />
        <motor name="right_ankle_x_motor" joint="right_ankle_x" />
        <motor name="right_ankle_y_motor" joint="right_ankle_y" />
        <motor name="left_hip_y_motor" joint="left_hip_y" />
        <motor name="left_hip_x_motor" joint="left_hip_x" />
        <motor name="left_hip_z_motor" joint="left_hip_z" />
        <motor name="left_knee_motor" joint="left_knee" />
        <motor name="left_ankle_x_motor" joint="left_ankle_x" />
        <motor name="left_ankle_y_motor" joint="left_ankle_y" />
    </actuator>

    <sensor>
        <!-- F/T sensors -->
        <!-- right foot -->
        <force name="RightFootForceSensor_fsensor" site="rf_force" />
        <torque name="RightFootForceSensor_tsensor" site="rf_force" />
        <!-- left foot -->
        <force name="LeftFootForceSensor_fsensor" site="lf_force" />
        <torque name="LeftFootForceSensor_tsensor" site="lf_force" />
  </sensor>
</mujoco>